Workbook
Name SlicerCache_Table_1_Col_8: #N/A

Sheet Data
B2: Key American Coca-Cola Retailers
B3: Beverage Sales & Operating Margin 2021
B5: Retailer | C5: Retailer ID | D5: Invoice Date | E5: Region | F5: State | G5: City | H5: Beverage Brand | I5: Price per Unit | J5: Units Sold | K5: Total Sales | L5: Operating Profit | M5: Operating Margin | N5: Month
B6: Sodapop | C6: 1185732 | D6: 44210 | E6: Northeast | F6: New York | G6: New York | H6: Coca-Cola | I6: 0.5 | J6: 12000 | K6: =I6*J6 -> 6000 | L6: =K6*M6 -> 3000 | M6: 0.5 | N6: =MONTH(D6) -> 1
B7: Sodapop | C7: 1185732 | D7: 44210 | E7: Northeast | F7: New York | G7: New York | H7: Diet Coke | I7: 0.5 | J7: 10000 | K7: =I7*J7 -> 5000 | L7: =K7*M7 -> 1500 | M7: 0.3 | N7: =MONTH(D7) -> 1
B8: Sodapop | C8: 1185732 | D8: 44210 | E8: Northeast | F8: New York | G8: New York | H8: Sprite | I8: 0.4 | J8: 10000 | K8: =I8*J8 -> 4000 | L8: =K8*M8 -> 1400 | M8: 0.35 | N8: =MONTH(D8) -> 1
B9: Sodapop | C9: 1185732 | D9: 44210 | E9: Northeast | F9: New York | G9: New York | H9: Fanta | I9: 0.45 | J9: 8500 | K9: =I9*J9 -> 3825 | L9: =K9*M9 -> 1338.75 | M9: 0.35 | N9: =MONTH(D9) -> 1
B10: Sodapop | C10: 1185732 | D10: 44210 | E10: Northeast | F10: New York | G10: New York | H10: Powerade | I10: 0.6 | J10: 9000 | K10: =I10*J10 -> 5400 | L10: =K10*M10 -> 1620 | M10: 0.3 | N10: =MONTH(D10) -> 1
B11: Sodapop | C11: 1185732 | D11: 44210 | E11: Northeast | F11: New York | G11: New York | H11: Dasani Water | I11: 0.5 | J11: 10000 | K11: =I11*J11 -> 5000 | L11: =K11*M11 -> 1250 | M11: 0.25 | N11: =MONTH(D11) -> 1
B12: Sodapop | C12: 1185732 | D12: 44239 | E12: Northeast | F12: New York | G12: New York | H12: Coca-Cola | I12: 0.5 | J12: 12500 | K12: =I12*J12 -> 6250 | L12: =K12*M12 -> 3125 | M12: 0.5 | N12: =MONTH(D12) -> 2
B13: Sodapop | C13: 1185732 | D13: 44239 | E13: Northeast | F13: New York | G13: New York | H13: Diet Coke | I13: 0.5 | J13: 9000 | K13: =I13*J13 -> 4500 | L13: =K13*M13 -> 1350 | M13: 0.3 | N13: =MONTH(D13) -> 2
B14: Sodapop | C14: 1185732 | D14: 44239 | E14: Northeast | F14: New York | G14: New York | H14: Sprite | I14: 0.4 | J14: 9500 | K14: =I14*J14 -> 3800 | L14: =K14*M14 -> 1330 | M14: 0.35 | N14: =MONTH(D14) -> 2
B15: Sodapop | C15: 1185732 | D15: 44239 | E15: Northeast | F15: New York | G15: New York | H15: Fanta | I15: 0.45 | J15: 8250 | K15: =I15*J15 -> 3712.5 | L15: =K15*M15 -> 1299.375 | M15: 0.35 | N15: =MONTH(D15) -> 2
B16: Sodapop | C16: 1185732 | D16: 44239 | E16: Northeast | F16: New York | G16: New York | H16: Powerade | I16: 0.6 | J16: 9000 | K16: =I16*J16 -> 5400 | L16: =K16*M16 -> 1620 | M16: 0.3 | N16: =MONTH(D16) -> 2
B17: Sodapop | C17: 1185732 | D17: 44239 | E17: Northeast | F17: New York | G17: New York | H17: Dasani Water | I17: 0.5 | J17: 10000 | K17: =I17*J17 -> 5000 | L17: =K17*M17 -> 1250 | M17: 0.25 | N17: =MONTH(D17) -> 2
... B509: Sodapop | C509: 1185732 | D509: 44533 | E509: Northeast | F509: Pennsylvania | G509: Philadelphia | H509: Dasani Water | I509: 0.75 | J509: 2750 | K509: =I509*J509 -> 2062.5 | L509: =K509*M509 -> 618.75 | M509: 0.3 | N509: =MONTH(D509) -> 12
A510: x | B510: FizzySip | C510: 1128299 | D510: 44211 | E510: West | F510: Nevada | G510: Las Vegas | H510: Coca-Cola | I510: 0.35 | J510: 4500 | K510: =I510*J510 -> 1575 | L510: =K510*M510 -> 630 | M510: 0.4 | N510: =MONTH(D510) -> 1
B511: FizzySip | C511: 1128299 | D511: 44211 | E511: West | F511: Nevada | G511: Las Vegas | H511: Diet Coke | I511: 0.45 | J511: 4500 | K511: =I511*J511 -> 2025 | L511: =K511*M511 -> 506.25 | M511: 0.25 | N511: =MONTH(D511) -> 1
B512: FizzySip | C512: 1128299 | D512: 44211 | E512: West | F512: Nevada | G512: Las Vegas | H512: Sprite | I512: 0.45 | J512: 4500 | K512: =I512*J512 -> 2025 | L512: =K512*M512 -> 810 | M512: 0.4 | N512: =MONTH(D512) -> 1
B513: FizzySip | C513: 1128299 | D513: 44211 | E513: West | F513: Nevada | G513: Las Vegas | H513: Fanta | I513: 0.45 | J513: 3000 | K513: =I513*J513 -> 1350 | L513: =K513*M513 -> 472.5 | M513: 0.35 | N513: =MONTH(D513) -> 1
B514: FizzySip | C514: 1128299 | D514: 44211 | E514: West | F514: Nevada | G514: Las Vegas | H514: Powerade | I514: 0.5 | J514: 2500 | K514: =I514*J514 -> 1250 | L514: =K514*M514 -> 687.5 | M514: 0.55 | N514: =MONTH(D514) -> 1
B515: FizzySip | C515: 1128299 | D515: 44211 | E515: West | F515: Nevada | G515: Las Vegas | H515: Dasani Water | I515: 0.45 | J515: 4750 | K515: =I515*J515 -> 2137.5 | L515: =K515*M515 -> 427.5 | M515: 0.2 | N515: =MONTH(D515) -> 1
B516: FizzySip | C516: 1128299 | D516: 44242 | E516: West | F516: Nevada | G516: Las Vegas | H516: Coca-Cola | I516: 0.35 | J516: 5250 | K516: =I516*J516 -> 1837.5 | L516: =K516*M516 -> 735 | M516: 0.4 | N516: =MONTH(D516) -> 2
B517: FizzySip | C517: 1128299 | D517: 44242 | E517: West | F517: Nevada | G517: Las Vegas | H517: Diet Coke | I517: 0.45 | J517: 4250 | K517: =I517*J517 -> 1912.5 | L517: =K517*M517 -> 478.125 | M517: 0.25 | N517: =MONTH(D517) -> 2
B518: FizzySip | C518: 1128299 | D518: 44242 | E518: West | F518: Nevada | G518: Las Vegas | H518: Sprite | I518: 0.45 | J518: 4250 | K518: =I518*J518 -> 1912.5 | L518: =K518*M518 -> 765 | M518: 0.4 | N518: =MONTH(D518) -> 2
B519: FizzySip | C519: 1128299 | D519: 44242 | E519: West | F519: Nevada | G519: Las Vegas | H519: Fanta | I519: 0.45 | J519: 2750 | K519: =I519*J519 -> 1237.5 | L519: =K519*M519 -> 433.125 | M519: 0.35 | N519: =MONTH(D519) -> 2
B520: FizzySip | C520: 1128299 | D520: 44242 | E520: West | F520: Nevada | G520: Las Vegas | H520: Powerade | I520: 0.5 | J520: 2000 | K520: =I520*J520 -> 1000 | L520: =K520*M520 -> 550 | M520: 0.55 | N520: =MONTH(D520) -> 2
B521: FizzySip | C521: 1128299 | D521: 44242 | E521: West | F521: Nevada | G521: Las Vegas | H521: Dasani Water | I521: 0.45 | J521: 4000 | K521: =I521*J521 -> 1800 | L521: =K521*M521 -> 360 | M521: 0.2 | N521: =MONTH(D521) -> 2
B522: FizzySip | C522: 1128299 | D522: 44269 | E522: West | F522: Nevada | G522: Las Vegas | H522: Coca-Cola | I522: 0.45 | J522: 5500 | K522: =I522*J522 -> 2475 | L522: =K522*M522 -> 990 | M522: 0.4 | N522: =MONTH(D522) -> 3
... B581: FizzySip | C581: 1128299 | D581: 44544 | E581: West | F581: Nevada | G581: Las Vegas | H581: Dasani Water | I581: 0.75 | J581: 5000 | K581: =I581*J581 -> 3750 | L581: =K581*M581 -> 562.5 | M581: 0.15 | N581: =MONTH(D581) -> 12
A582: x | B582: FizzySip | C582: 1128299 | D582: 44201 | E582: West | F582: Colorado | G582: Denver | H582: Coca-Cola | I582: 0.3 | J582: 4250 | K582: =I582*J582 -> 1275 | L582: =K582*M582 -> 446.25 | M582: 0.35 | N582: =MONTH(D582) -> 1
B583: FizzySip | C583: 1128299 | D583: 44201 | E583: West | F583: Colorado | G583: Denver | H583: Diet Coke | I583: 0.4 | J583: 4250 | K583: =I583*J583 -> 1700 | L583: =K583*M583 -> 340 | M583: 0.2 | N583: =MONTH(D583) -> 1
B584: FizzySip | C584: 1128299 | D584: 44201 | E584: West | F584: Colorado | G584: Denver | H584: Sprite | I584: 0.4 | J584: 4250 | K584: =I584*J584 -> 1700 | L584: =K584*M584 -> 595 | M584: 0.35 | N584: =MONTH(D584) -> 1
B585: FizzySip | C585: 1128299 | D585: 44201 | E585: West | F585: Colorado | G585: Denver | H585: Fanta | I585: 0.4 | J585: 2750 | K585: =I585*J585 -> 1100 | L585: =K585*M585 -> 330 | M585: 0.3 | N585: =MONTH(D585) -> 1
B586: FizzySip | C586: 1128299 | D586: 44201 | E586: West | F586: Colorado | G586: Denver | H586: Powerade | I586: 0.45 | J586: 2250 | K586: =I586*J586 -> 1012.5 | L586: =K586*M586 -> 506.25 | M586: 0.5 | N586: =MONTH(D586) -> 1
B587: FizzySip | C587: 1128299 | D587: 44201 | E587: West | F587: Colorado | G587: Denver | H587: Dasani Water | I587: 0.4 | J587: 4750 | K587: =I587*J587 -> 1900 | L587: =K587*M587 -> 285 | M587: 0.15 | N587: =MONTH(D587) -> 1
B588: FizzySip | C588: 1128299 | D588: 44232 | E588: West | F588: Colorado | G588: Denver | H588: Coca-Cola | I588: 0.3 | J588: 5250 | K588: =I588*J588 -> 1575 | L588: =K588*M588 -> 551.25 | M588: 0.35 | N588: =MONTH(D588) -> 2
B589: FizzySip | C589: 1128299 | D589: 44232 | E589: West | F589: Colorado | G589: Denver | H589: Diet Coke | I589: 0.4 | J589: 4250 | K589: =I589*J589 -> 1700 | L589: =K589*M589 -> 340 | M589: 0.2 | N589: =MONTH(D589) -> 2
B590: FizzySip | C590: 1128299 | D590: 44232 | E590: West | F590: Colorado | G590: Denver | H590: Sprite | I590: 0.4 | J590: 4250 | K590: =I590*J590 -> 1700 | L590: =K590*M590 -> 595 | M590: 0.35 | N590: =MONTH(D590) -> 2
B591: FizzySip | C591: 1128299 | D591: 44232 | E591: West | F591: Colorado | G591: Denver | H591: Fanta | I591: 0.4 | J591: 2750 | K591: =I591*J591 -> 1100 | L591: =K591*M591 -> 330 | M591: 0.3 | N591: =MONTH(D591) -> 2
...

Sheet Beginner
A2: BASIC CLEANING: - Dates are in a recognizable format (e.g., 1/1/2023) - Numbers (like Sales) are properly formatted (currency or number) - Categorical values (like Brand, Region) are consistent
B8: Month | C8: SUM of Total Sales
B9: 1 | C9: 510750
B10: 2 | C10: 484975
B11: 3 | C11: 483530
B12: 4 | C12: 494887.5
B13: 5 | C13: 673572.5
B14: 6 | C14: 903837.5
B15: 7 | C15: 1041437.5
B16: 8 | C16: 945275
B17: 9 | C17: 681000
B18: 10 | C18: 623375
B19: 11 | C19: 795612.5
B20: 12 | C20: 1045775
B21: Grand Total | C21: 8684027.5
B31: Region | C31: SUM of Total Sales
B32: Midwest | C32: 1150110
B33: Northeast | C33: 1788347.5
B34: South | C34: 1291535
B35: Southeast | C35: 1618935
B36: West | C36: 2835100
B37: Grand Total | C37: 8684027.5
B55: Retailer | C55: SUM of Total Sales
B56: BevCo | C56: 1291535
B57: DreamCo | C57: 404412.5
B58: FizzySip | C58: 2584450
B59: Sodapop | C59: 4403630
B60: Grand Total | C60: 8684027.5
B75: Beverage Brand | C75: SUM of Total Sales
B76: Coca-Cola | C76: 2015890
B77: Dasani Water | C77: 1725837.5
B78: Diet Coke | C78: 1481425
B79: Fanta | C79: 1031650
B80: Powerade | C80: 1193637.5
B81: Sprite | C81: 1235587.5
B82: Grand Total | C82: 8684027.5
B99: Beverage Brand | C99: SUM of Units Sold
B100: Coca-Cola | C100: 4133250
B101: Dasani Water | C101: 3000250
B102: Diet Coke | C102: 3001500
...

Sheet Intermediate
B6: SUM of Total Sales | C6: Beverage Brand
B7: Month | C7: Coca-Cola | D7: Dasani Water | E7: Diet Coke | F7: Fanta | G7: Powerade | H7: Sprite
B8: 1 | C8: 110012.5 | D8: 93662.5 | E8: 94112.5 | F8: 58700 | G8: 77350 | H8: 76912.5
B9: 2 | C9: 121250 | D9: 84950 | E9: 80150 | F9: 53875 | G9: 73137.5 | H9: 71612.5
B10: 3 | C10: 123667.5 | D10: 82525 | E10: 85575 | F10: 55062.5 | G10: 63075 | H10: 73625
B11: 4 | C11: 128250 | D11: 99987.5 | E11: 79112.5 | F11: 53962.5 | G11: 64225 | H11: 69350
B12: 5 | C12: 166372.5 | D12: 150300 | E12: 103350 | F12: 76162.5 | G12: 85087.5 | H12: 92300
B13: 6 | C13: 193825 | D13: 213387.5 | E13: 140500 | F13: 110500 | G13: 116975 | H13: 128650
B14: 7 | C14: 237587.5 | D14: 212825 | E14: 174187.5 | F14: 119837.5 | G14: 146750 | H14: 150250
B15: 8 | C15: 232600 | D15: 161062.5 | E15: 179900 | F15: 107462.5 | G15: 119500 | H15: 144750
B16: 9 | C16: 170737.5 | D16: 119562.5 | E16: 131187.5 | F16: 76762.5 | G16: 91400 | H16: 91350
B17: 10 | C17: 146575 | D17: 125087.5 | E17: 113700 | F17: 72837.5 | G17: 83025 | H17: 82150
B18: 11 | C18: 150787.5 | D18: 181900 | E18: 118612.5 | F18: 111125 | G18: 127850 | H18: 105337.5
B19: 12 | C19: 234225 | D19: 200587.5 | E19: 181037.5 | F19: 135362.5 | G19: 145262.5 | H19: 149300
B32: SUM of Total Sales | C32: Beverage Brand
B33: Region | C33: Coca-Cola | D33: Dasani Water | E33: Diet Coke | F33: Fanta | G33: Powerade | H33: Sprite
B34: Midwest | C34: 344527.5 | D34: 243062.5 | E34: 178675 | F34: 103237.5 | G34: 147175 | H34: 133432.5
B35: Northeast | C35: 498157.5 | D35: 357712.5 | E35: 277050 | F35: 188862.5 | G35: 242875 | H35: 223690
B36: South | C36: 248022.5 | D36: 267837.5 | E36: 231450 | F36: 165750 | G36: 171050 | H36: 207425
B37: Southeast | C37: 375482.5 | D37: 319662.5 | E37: 253100 | F37: 198750 | G37: 262775 | H37: 209165
B38: West | C38: 549700 | D38: 537562.5 | E38: 541150 | F38: 375050 | G38: 369762.5 | H38: 461875
B54: SUM of Units Sold | C54: Beverage Brand
B55: Month | C55: Coca-Cola | D55: Dasani Water | E55: Diet Coke | F55: Fanta | G55: Powerade | H55: Sprite
B56: 1 | C56: 313000 | D56: 236750 | E56: 243000 | F56: 159500 | G56: 162500 | H56: 233000
B57: 2 | C57: 339250 | D57: 224500 | E57: 201750 | F57: 144750 | G57: 152500 | H57: 211500
B58: 3 | C58: 330750 | D58: 199000 | E58: 203000 | F58: 136750 | G58: 128500 | H58: 206250
B59: 4 | C59: 320750 | D59: 213000 | E59: 187750 | F59: 141000 | G59: 127500 | H59: 185750
B60: 5 | C60: 342250 | D60: 254500 | E60: 219000 | F60: 171000 | G60: 160750 | H60: 207500
B61: 6 | C61: 378000 | D61: 312500 | E61: 271750 | F61: 218750 | G61: 196250 | H61: 247500
B62: 7 | C62: 409500 | D62: 313250 | E62: 301500 | F62: 224250 | G62: 238250 | H62: 275750
B63: 8 | C63: 390250 | D63: 265750 | E63: 306000 | F63: 214500 | G63: 205750 | H63: 271750
B64: 9 | C64: 332750 | D64: 225500 | E64: 260500 | F64: 176000 | G64: 177000 | H64: 205500
B65: 10 | C65: 296500 | D65: 215750 | E65: 243750 | F65: 161000 | G65: 156250 | H65: 180000
B66: 11 | C66: 304000 | D66: 257750 | E66: 257250 | F66: 210250 | G66: 195000 | H66: 218250
B67: 12 | C67: 376250 | D67: 282000 | E67: 306250 | F67: 233500 | G67: 220500 | H67: 258500

Sheet Advanced
B4: SUM of Units Sold | C4: Region | D4: Beverage Brand
C5: Midwest Total | D5: Northeast Total | E5: South Total | F5: Southeast Total | G5: West Total
B6: Month
B7: 1 | C7: 235000 | D7: 271000 | E7: 242000 | F7: 278500 | G7: 321250
B8: 2 | C8: 219500 | D8: 261000 | E8: 218500 | F8: 266750 | G8: 308500
B9: 3 | C9: 203650 | D9: 243350 | E9: 207600 | F9: 245900 | G9: 303750
B10: 4 | C10: 182750 | D10: 234000 | E10: 220000 | F10: 243000 | G10: 296000
B11: 5 | C11: 208900 | D11: 283100 | E11: 262100 | F11: 266400 | G11: 334500
B12: 6 | C12: 254000 | D12: 324250 | E12: 289000 | F12: 291250 | G12: 466250
B13: 7 | C13: 288000 | D13: 344750 | E13: 319000 | F13: 313750 | G13: 497000
B14: 8 | C14: 268250 | D14: 319250 | E14: 298750 | F14: 305000 | G14: 462750
B15: 9 | C15: 222750 | D15: 262750 | E15: 248250 | F15: 272750 | G15: 370750
B16: 10 | C16: 193500 | D16: 239750 | E16: 217500 | F16: 256250 | G16: 346250
B17: 11 | C17: 227150 | D17: 282350 | E17: 250600 | F17: 265400 | G17: 417000
B18: 12 | C18: 279500 | D18: 329000 | E18: 291500 | F18: 299500 | G18: 477500
B43: Retailer | C43: Beverage Brand | D43: SUM of Units Sold
B44: BevCo Total | D44: 3064800
B45: DreamCo Total | D45: 820500
B46: FizzySip Total | D46: 4109000
B47: Sodapop Total | D47: 9153950

Sheet Addtional Analysis 
A1: Addtional Analysis
A3: Monthly Trend Analysis
A4: Revenue Trends: Monitor total sales progression month-over-month Profitability Trends: Analyze operating profit changes across months Seasonal Patterns: Identify which months perform best/worst for each brand (Add weather data)
A6: Brand Performance Analysis
A7: - Revenue Contribution: Calculate each brand's percentage of total sales - Profit Contribution: Determine which brands generate most operating profit - Volume Analysis: Compare units sold across different brands - Price Point Analysis: Evaluate how pricing affects sales volume per brand - Margin Efficiency: Rank brands by operating margin percentage
A9: Profitability Deep Dive
A10: - Profit per Unit: Calculate operating profit divided by units sold - Revenue vs Profit Correlation: Identify brands with best profit efficiency - Margin Stability: Track how operating margins change over time - Break-even Analysis: Determine minimum sales volumes needed for profitability
